Workbook

Sheet VAB_trim
A1: Fecha | B1: VAB Sector Público | C1: VAB Sector Privado | D1: VAB Industria Manufacturera | E1: VAB General
A2: 38077 | B2: 37002.446 | C2: 353784.49 | D2: 86448.022 | E2: 390786.93 | G2: 390786.93
A3: 38168 | B3: 38178.22 | C3: 401564.36 | D3: 91700.169 | E3: 439742.58 | G3: 439742.58
A4: 38260 | B4: 38711.16 | C4: 367867.78 | D4: 93728.826 | E4: 406578.94 | G4: 406578.94
A5: 38352 | B5: 39088.401 | C5: 373512.98 | D5: 95588.305 | E5: 412601.38 | G5: 412601.38
A6: 38442 | B6: 39380.334 | C6: 380260.52 | D6: 91736.478 | E6: 419640.85 | G6: 419640.85
A7: 38533 | B7: 40466.253 | C7: 458067.99 | D7: 99507.401 | E7: 498534.24 | G7: 498534.24
A8: 38625 | B8: 40857.848 | C8: 396418.92 | D8: 100147.72 | E8: 437276.76 | G8: 437276.76
A9: 38717 | B9: 41525.92 | C9: 404235.55 | D9: 103351.26 | E9: 445761.47 | G9: 445761.47
A10: 38807 | B10: 40657.87 | C10: 410865.7 | D10: 99844.349 | E10: 451523.57 | G10: 451523.57
A11: 38898 | B11: 41863.183 | C11: 484004.03 | D11: 107920.82 | E11: 525867.22 | G11: 525867.22
A12: 38990 | B12: 42537.852 | C12: 435334.63 | D12: 110311.8 | E12: 477872.48 | G12: 477872.48
A13: 39082 | B13: 42880.133 | C13: 439812.95 | D13: 112586.65 | E13: 482693.08 | G13: 482693.08
... A21: 39813 | B21: 47250.549 | C21: 466208.07 | D21: 116905.55 | E21: 513458.62 | G21: 513458.62
A22: 39903 | B22: 46500.43 | C22: 436499.15 | D22: 99731.98 | E22: 482999.58 | G22: 482999.58 | H22: 100
A23: 39994 | B23: 47386.672 | C23: 485344.88 | D23: 110280.78 | E23: 532731.56 | G23: 532731.56
A24: 40086 | B24: 49121.109 | C24: 463696.34 | D24: 115427.8 | E24: 512817.45 | G24: 512817.45
A25: 40178 | B25: 49410.632 | C25: 468776.03 | D25: 119600.38 | E25: 518186.66 | G25: 518186.66
A26: 40268 | B26: 49028.356 | C26: 464674.46 | D26: 109908.24 | E26: 513702.81 | G26: 513702.81
A27: 40359 | B27: 50129.628 | C27: 571178.86 | D27: 123636.55 | E27: 621308.49 | G27: 621308.49
A28: 40451 | B28: 50012.801 | C28: 507166.94 | D28: 128980.7 | E28: 557179.74 | G28: 557179.74
A29: 40543 | B29: 50223.477 | C29: 509575.63 | D29: 131060.27 | E29: 559799.11 | G29: 559799.11
A30: 40633 | B30: 50305.841 | C30: 501866.69 | D30: 121432.84 | E30: 552172.53 | G30: 552172.53
A31: 40724 | B31: 51462.327 | C31: 595436.31 | D31: 136012.85 | E31: 646898.63 | G31: 646898.63
A32: 40816 | B32: 52133.649 | C32: 538311.43 | D32: 138227.84 | E32: 590445.08 | G32: 590445.08
A33: 40908 | B33: 52173.618 | C33: 532391.22 | D33: 135753.51 | E33: 584564.83 | G33: 584564.83
A34: 40999 | B34: 52383.84 | C34: 506007.1 | D34: 120673.38 | E34: 558390.94 | G34: 558390.94
... A87: 45838 | B87: 64954.845 | C87: 581772.45 | D87: 108818.67 | E87: 646727.3 | G87: 646727.3

Sheet Salarios_Total_General
A1: Fecha | B1: Salarios_Reales_Totales_Trim
A2: 40999 | B2: 100
A3: 41090 | B3: 100.15118
A4: 41182 | B4: 101.35479
A5: 41274 | B5: 101.77182
A6: 41364 | B6: 99.863436
A7: 41455 | B7: 100.97326
A8: 41547 | B8: 101.5067
A9: 41639 | B9: 98.874002
A10: 41729 | B10: 91.939254
A11: 41820 | B11: 93.063002
A12: 41912 | B12: 94.753744
A13: 42004 | B13: 93.989291
... A55: 45838 | B55: 71.361445
B56: 73.401481

Sheet Salario_sector_trim
A1: Fecha | B1: Sector Privado | C1: Sector Público
A2: 38717 | B2: 92.956762 | C2: 89.360636
A3: 38807 | B3: 94.701415 | C3: 87.963153
A4: 38898 | B4: 97.764405 | C4: 87.685878
A5: 38990 | B5: 102.11357 | C5: 91.083331
A6: 39082 | B6: 103.80971 | C6: 95.917003
A7: 39172 | B7: 103.49801 | C7: 95.399589
A8: 39263 | B8: 102.56887 | C8: 94.217056
A9: 39355 | B9: 100.53909 | C9: 98.519678
A10: 39447 | B10: 101.50694 | C10: 100.17526
A11: 39538 | B11: 95.501104 | C11: 98.482646
A12: 39629 | B12: 94.975193 | C12: 94.327395
A13: 39721 | B13: 97.963401 | C13: 99.578262
... A80: 45838 | B80: 82.953465 | C80: 49.101108
A81: 45930

Sheet Salarios_Ind_Trim
A1: Fecha | B1: Salarios_Ind_Trim | J1: Salario_Ind_pesos_Dic_2004
A2: 38352 | B2: 92.125032 | G2: 38261 | H2: 31033 | I2: 38352 | J2: 36830.667 | K2: =+(J2/$J$19)*100 -> 92.125032
A3: 38442 | B3: 82.69258 | G3: 38292 | H3: 31475 | I3: 38442 | J3: 33059.667 | K3: =+(J3/$J$19)*100 -> 82.69258
A4: 38533 | B4: 94.388721 | G4: 38322 | H4: 47984 | I4: 38533 | J4: 37735.667 | K4: =+(J4/$J$19)*100 -> 94.388721
A5: 38625 | B5: 84.892902 | G5: 38353 | H5: 34242 | I5: 38625 | J5: 33939.333 | K5: =+(J5/$J$19)*100 -> 84.892902
A6: 38717 | B6: 105.1402 | G6: 38384 | H6: 31359 | I6: 38717 | J6: 42034 | K6: =+(J6/$J$19)*100 -> 105.1402
A7: 38807 | B7: 90.929405 | G7: 38412 | H7: 33578 | I7: 38807 | J7: 36352.667 | K7: =+(J7/$J$19)*100 -> 90.929405
A8: 38898 | B8: 104.23722 | G8: 38443 | H8: 32988 | I8: 38898 | J8: 41673 | K8: =+(J8/$J$19)*100 -> 104.23722
A9: 38990 | B9: 96.022912 | G9: 38473 | H9: 32789 | I9: 38990 | J9: 38389 | K9: =+(J9/$J$19)*100 -> 96.022912
A10: 39082 | B10: 113.21694 | G10: 38504 | H10: 47430 | I10: 39082 | J10: 45263 | K10: =+(J10/$J$19)*100 -> 113.21694
A11: 39172 | B11: 98.505882 | G11: 38534 | H11: 33474 | I11: 39172 | J11: 39381.667 | K11: =+(J11/$J$19)*100 -> 98.505882
A12: 39263 | B12: 111.15752 | G12: 38565 | H12: 34042 | I12: 39263 | J12: 44439.667 | K12: =+(J12/$J$19)*100 -> 111.15752
A13: 39355 | B13: 95.433436 | G13: 38596 | H13: 34302 | I13: 39355 | J13: 38153.333 | K13: =+(J13/$J$19)*100 -> 95.433436
... A84: 45838 | B84: 109.35324 | G84: 40756 | H84: 47428 | I84: 45838 | J84: 43718.333 | K84: =+(J84/$J$19)*100 -> 109.35324
A85: 45930 | G85: 40787 | H85: 46638 | I85: 45930 | M85: =+(L85/$J$19)*100 -> 0
G86: 40817 | H86: 47546 | M86: =+(L86/$J$19)*100 -> 0
G87: 40848 | H87: 47782 | M87: =+(L87/$J$19)*100 -> 0
G88: 40878 | H88: 72930 | M88: =+(L88/$J$19)*100 -> 0
G89: 40909 | H89: 49765 | M89: =+(L89/$J$19)*100 -> 0
G90: 40940 | H90: 46650 | M90: =+(L90/$J$19)*100 -> 0
G91: 40969 | H91: 48263 | M91: =+(L91/$J$19)*100 -> 0
G92: 41000 | H92: 45819 | M92: =+(L92/$J$19)*100 -> 0
G93: 41030 | H93: 47269 | M93: =+(L93/$J$19)*100 -> 0
G94: 41061 | H94: 69180 | M94: =+(L94/$J$19)*100 -> 0
G95: 41091 | H95: 49880 | M95: =+(L95/$J$19)*100 -> 0
G96: 41122 | H96: 49690 | M96: =+(L96/$J$19)*100 -> 0
G97: 41153 | H97: 48649 | M97: =+(L97/$J$19)*100 -> 0
... G250: 45809 | H250: 55105 | M250: =+(L250/$J$19)*100 -> 0
M251: =+(L251/$J$19)*100 -> 0
M252: =+(L252/$J$19)*100 -> 0
M253: =+(L253/$J$19)*100 -> 0
M254: =+(L254/$J$19)*100 -> 0
M255: =+(L255/$J$19)*100 -> 0
M256: =+(L256/$J$19)*100 -> 0
M257: =+(L257/$J$19)*100 -> 0
M258: =+(L258/$J$19)*100 -> 0
M259: =+(L259/$J$19)*100 -> 0
M260: =+(L260/$J$19)*100 -> 0
M261: =+(L261/$J$19)*100 -> 0
M262: =+(L262/$J$19)*100 -> 0
...

Sheet Puesto_desest_trim
A1: Fecha | B1: Puestos_sector_privado | C1: Puestos_sector_publico TRIMESTRAL | D1: Puestos_Industria | E1: Puestos_Comercio | F1: Puestos_Transporte | G1: Puestos_Acts_Inmob | H1: Puestos_Total
A2: 39903 | B2: 5608.4 | D2: 1176.932 | E2: 1016.1033 | F2: 488.106 | G2: 824.987
A3: 39994 | B3: 5572.6667 | D3: 1159.49 | E3: 999.822 | F3: 484.93033 | G3: 796.30133
A4: 40086 | B4: 5580.2333 | D4: 1161.7117 | E4: 1000.086 | F4: 483.77133 | G4: 795.25633
A5: 40178 | B5: 5603.6 | D5: 1167.1413 | E5: 1016.8633 | F5: 486.92 | G5: 807.953
A6: 40268 | B6: 5638 | D6: 1173.7017 | E6: 1031.748 | F6: 490.96467 | G6: 829.93833
A7: 40359 | B7: 5692.4333 | D7: 1185.76 | E7: 1027.784 | F7: 493.43667 | G7: 818.673
A8: 40451 | B8: 5746.9333 | D8: 1195.1167 | E8: 1037.859 | F8: 497.70633 | G8: 821.604
A9: 40543 | B9: 5809.4333 | D9: 1202.474 | E9: 1060.8177 | F9: 503.53833 | G9: 844.75267
A10: 40633 | B10: 5889.7 | D10: 1218.1557 | E10: 1080.2083 | F10: 511.552 | G10: 864.804
A11: 40724 | B11: 5966.1333 | D11: 1233.8807 | E11: 1075.0817 | F11: 515.79833 | G11: 854.07133
A12: 40816 | B12: 6021.6333 | D12: 1245.6263 | E12: 1085.137 | F12: 521.477 | G12: 858.13767
A13: 40908 | B13: 6067.1667 | D13: 1254.6877 | E13: 1105.2503 | F13: 527.71733 | G13: 872.59633
A14: 40999 | B14: 6067.6333 | C14: 2594.3283 | D14: 1254.579 | E14: 1115.306 | F14: 531.87467 | G14: 881.50033 | H14: =+Puesto_desest_trim[[#This Row],[Puestos_sector_privado ]]+Puesto_desest_trim[[#This Row],[Puestos_sector_publico TRIMESTRAL]] -> 8661.9617 | J14: 2549.906 | K14: =IF(MOD(ROW()-14,3)=0,AVERAGE(INDIRECT("J"&ROW()&":J"&(ROW()+2))),"") -> 2594.3283 | M14: 2594.3283 | O14: 1182.914 | Q14: =IF(MOD(ROW()-14,3)=0,AVERAGE(INDIRECT("O"&ROW()&":O"&(ROW()+2))),"") -> 1176.932 | R14: 1176.932
A15: 41090 | B15: 6062.1333 | C15: 2618.5813 | D15: 1252.8607 | E15: 1100.475 | F15: 531.28633 | G15: 855.02433 | H15: =+Puesto_desest_trim[[#This Row],[Puestos_sector_privado ]]+Puesto_desest_trim[[#This Row],[Puestos_sector_publico TRIMESTRAL]] -> 8680.7147 | J15: 2610.544 | K15: =IF(MOD(ROW()-14,3)=0,AVERAGE(INDIRECT("J"&ROW()&":J"&(ROW()+2))),"") | M15: 2618.5813 | O15: 1178.64 | Q15: =IF(MOD(ROW()-14,3)=0,AVERAGE(INDIRECT("O"&ROW()&":O"&(ROW()+2))),"") | R15: 1159.49
A16: 41182 | B16: 6060.5 | C16: 2632.701 | D16: 1254.404 | E16: 1099.7247 | F16: 532.77267 | G16: 845.75167 | H16: =+Puesto_desest_trim[[#This Row],[Puestos_sector_privado ]]+Puesto_desest_trim[[#This Row],[Puestos_sector_publico TRIMESTRAL]] -> 8693.201 | J16: 2622.535 | K16: =IF(MOD(ROW()-14,3)=0,AVERAGE(INDIRECT("J"&ROW()&":J"&(ROW()+2))),"") | M16: 2632.701 | O16: 1169.242 | Q16: =IF(MOD(ROW()-14,3)=0,AVERAGE(INDIRECT("O"&ROW()&":O"&(ROW()+2))),"") | R16: 1161.7117
A17: 41274 | B17: 6074.4 | C17: 2651.594 | D17: 1258.7603 | E17: 1115.4003 | F17: 535.92933 | G17: 853.52367 | H17: =+Puesto_desest_trim[[#This Row],[Puestos_sector_privado ]]+Puesto_desest_trim[[#This Row],[Puestos_sector_publico TRIMESTRAL]] -> 8725.994 | J17: 2625.419 | K17: =IF(MOD(ROW()-14,3)=0,AVERAGE(INDIRECT("J"&ROW()&":J"&(ROW()+2))),"") -> 2618.5813 | M17: 2651.594 | O17: 1160.519 | Q17: =IF(MOD(ROW()-14,3)=0,AVERAGE(INDIRECT("O"&ROW()&":O"&(ROW()+2))),"") -> 1159.49 | R17: 1167.1413
A18: 41364 | B18: 6098 | C18: 2720.032 | D18: 1263.944 | E18: 1127.386 | F18: 538.302 | G18: 862.47867 | H18: =+Puesto_desest_trim[[#This Row],[Puestos_sector_privado ]]+Puesto_desest_trim[[#This Row],[Puestos_sector_publico TRIMESTRAL]] -> 8818.032 | J18: 2597.884 | K18: =IF(MOD(ROW()-14,3)=0,AVERAGE(INDIRECT("J"&ROW()&":J"&(ROW()+2))),"") | M18: 2720.032 | O18: 1157.545 | Q18: =IF(MOD(ROW()-14,3)=0,AVERAGE(INDIRECT("O"&ROW()&":O"&(ROW()+2))),"") | R18: 1173.7017
A19: 41455 | B19: 6109.3333 | C19: 2785.0943 | D19: 1265.098 | E19: 1111.7417 | F19: 538.466 | G19: 842.99733 | H19: =+Puesto_desest_trim[[#This Row],[Puestos_sector_privado ]]+Puesto_desest_trim[[#This Row],[Puestos_sector_publico TRIMESTRAL]] -> 8894.4277 | J19: 2632.441 | K19: =IF(MOD(ROW()-14,3)=0,AVERAGE(INDIRECT("J"&ROW()&":J"&(ROW()+2))),"") | M19: 2785.0943 | O19: 1160.406 | Q19: =IF(MOD(ROW()-14,3)=0,AVERAGE(INDIRECT("O"&ROW()&":O"&(ROW()+2))),"") | R19: 1185.76
A20: 41547 | B20: 6116.8 | C20: 2814.654 | D20: 1265.372 | E20: 1113.4733 | F20: 541.911 | G20: 838.06 | H20: =+Puesto_desest_trim[[#This Row],[Puestos_sector_privado ]]+Puesto_desest_trim[[#This Row],[Puestos_sector_publico TRIMESTRAL]] -> 8931.454 | J20: 2628.821 | K20: =IF(MOD(ROW()-14,3)=0,AVERAGE(INDIRECT("J"&ROW()&":J"&(ROW()+2))),"") -> 2632.701 | M20: 2814.654 | O20: 1159.772 | Q20: =IF(MOD(ROW()-14,3)=0,AVERAGE(INDIRECT("O"&ROW()&":O"&(ROW()+2))),"") -> 1161.7117 | R20: 1195.1167
A21: 41639 | B21: 6122.1 | C21: 2842.741 | D21: 1265.3943 | E21: 1126.8263 | F21: 545.33633 | G21: 846.55967 | H21: =+Puesto_desest_trim[[#This Row],[Puestos_sector_privado ]]+Puesto_desest_trim[[#This Row],[Puestos_sector_publico TRIMESTRAL]] -> 8964.841 | J21: 2636.879 | K21: =IF(MOD(ROW()-14,3)=0,AVERAGE(INDIRECT("J"&ROW()&":J"&(ROW()+2))),"") | M21: 2842.741 | O21: 1161.443 | Q21: =IF(MOD(ROW()-14,3)=0,AVERAGE(INDIRECT("O"&ROW()&":O"&(ROW()+2))),"") | R21: 1202.474
A22: 41729 | B22: 6105.1667 | C22: 2845.111 | D22: 1257.207 | E22: 1135.12 | F22: 545.536 | G22: 846.32967 | H22: =+Puesto_desest_trim[[#This Row],[Puestos_sector_privado ]]+Puesto_desest_trim[[#This Row],[Puestos_sector_publico TRIMESTRAL]] -> 8950.2777 | J22: 2632.403 | K22: =IF(MOD(ROW()-14,3)=0,AVERAGE(INDIRECT("J"&ROW()&":J"&(ROW()+2))),"") | M22: 2845.111 | O22: 1163.92 | Q22: =IF(MOD(ROW()-14,3)=0,AVERAGE(INDIRECT("O"&ROW()&":O"&(ROW()+2))),"") | R22: 1218.1557
A23: 41820 | B23: 6103.2333 | C23: 2883.8693 | D23: 1250.819 | E23: 1116.2217 | F23: 544.30467 | G23: 825.83167 | H23: =+Puesto_desest_trim[[#This Row],[Puestos_sector_privado ]]+Puesto_desest_trim[[#This Row],[Puestos_sector_publico TRIMESTRAL]] -> 8987.1027 | J23: 2640.574 | K23: =IF(MOD(ROW()-14,3)=0,AVERAGE(INDIRECT("J"&ROW()&":J"&(ROW()+2))),"") -> 2651.594 | M23: 2883.8693 | O23: 1167.597 | Q23: =IF(MOD(ROW()-14,3)=0,AVERAGE(INDIRECT("O"&ROW()&":O"&(ROW()+2))),"") -> 1167.1413 | R23: 1233.8807
A24: 41912 | B24: 6114.1667 | C24: 2911.6023 | D24: 1245.9867 | E24: 1116.7573 | F24: 545.85133 | G24: 817.78667 | H24: =+Puesto_desest_trim[[#This Row],[Puestos_sector_privado ]]+Puesto_desest_trim[[#This Row],[Puestos_sector_publico TRIMESTRAL]] -> 9025.769 | J24: 2655.837 | K24: =IF(MOD(ROW()-14,3)=0,AVERAGE(INDIRECT("J"&ROW()&":J"&(ROW()+2))),"") | M24: 2911.6023 | O24: 1166.851 | Q24: =IF(MOD(ROW()-14,3)=0,AVERAGE(INDIRECT("O"&ROW()&":O"&(ROW()+2))),"") | R24: 1245.6263
A25: 42004 | B25: 6135.3333 | C25: 2938.151 | D25: 1243.2917 | E25: 1126.358 | F25: 548.34933 | G25: 831.65 | H25: =+Puesto_desest_trim[[#This Row],[Puestos_sector_privado ]]+Puesto_desest_trim[[#This Row],[Puestos_sector_publico TRIMESTRAL]] -> 9073.4843 | J25: 2658.371 | K25: =IF(MOD(ROW()-14,3)=0,AVERAGE(INDIRECT("J"&ROW()&":J"&(ROW()+2))),"") | M25: 2938.151 | O25: 1166.976 | Q25: =IF(MOD(ROW()-14,3)=0,AVERAGE(INDIRECT("O"&ROW()&":O"&(ROW()+2))),"") | R25: 1254.6877
... A67: 45838 | B67: 6262.4 | C67: 3406.1323 | D67: 1160.009 | E67: 1250.2407 | F67: 514.631 | G67: 891.43333 | H67: =+Puesto_desest_trim[[#This Row],[Puestos_sector_privado ]]+Puesto_desest_trim[[#This Row],[Puestos_sector_publico TRIMESTRAL]] -> 9668.5323 | J67: 3109.82 | K67: =IF(MOD(ROW()-14,3)=0,AVERAGE(INDIRECT("J"&ROW()&":J"&(ROW()+2))),"") | M67: 3406.1323 | O67: 1264.602 | Q67: =IF(MOD(ROW()-14,3)=0,AVERAGE(INDIRECT("O"&ROW()&":O"&(ROW()+2))),"") | R67: 1151.452
J68: 3113.79 | K68: =IF(MOD(ROW()-14,3)=0,AVERAGE(INDIRECT("J"&ROW()&":J"&(ROW()+2))),"") -> 3114.814 | M68: 3406.2553 | O68: 1265.297 | Q68: =IF(MOD(ROW()-14,3)=0,AVERAGE(INDIRECT("O"&ROW()&":O"&(ROW()+2))),"") -> 1265.372 | R68: 1163.8533
J69: 3115.053 | K69: =IF(MOD(ROW()-14,3)=0,AVERAGE(INDIRECT("J"&ROW()&":J"&(ROW()+2))),"") | M69: 3399.507 | O69: 1265.236 | Q69: =IF(MOD(ROW()-14,3)=0,AVERAGE(INDIRECT("O"&ROW()&":O"&(ROW()+2))),"") | R69: 1172.401
J70: 3115.599 | K70: =IF(MOD(ROW()-14,3)=0,AVERAGE(INDIRECT("J"&ROW()&":J"&(ROW()+2))),"") | O70: 1265.583 | Q70: =IF(MOD(ROW()-14,3)=0,AVERAGE(INDIRECT("O"&ROW()&":O"&(ROW()+2))),"") | R70: 1181.143
J71: 3112.725 | K71: =IF(MOD(ROW()-14,3)=0,AVERAGE(INDIRECT("J"&ROW()&":J"&(ROW()+2))),"") -> 3117.0803 | O71: 1265.92 | Q71: =IF(MOD(ROW()-14,3)=0,AVERAGE(INDIRECT("O"&ROW()&":O"&(ROW()+2))),"") -> 1265.3943 | R71: 1190.273
J72: 3117.725 | K72: =IF(MOD(ROW()-14,3)=0,AVERAGE(INDIRECT("J"&ROW()&":J"&(ROW()+2))),"") | O72: 1265.402 | Q72: =IF(MOD(ROW()-14,3)=0,AVERAGE(INDIRECT("O"&ROW()&":O"&(ROW()+2))),"") | R72: 1196.8947
J73: 3120.791 | K73: =IF(MOD(ROW()-14,3)=0,AVERAGE(INDIRECT("J"&ROW()&":J"&(ROW()+2))),"") | O73: 1264.861 | Q73: =IF(MOD(ROW()-14,3)=0,AVERAGE(INDIRECT("O"&ROW()&":O"&(ROW()+2))),"") | R73: 1193.9457
J74: 3123.067 | K74: =IF(MOD(ROW()-14,3)=0,AVERAGE(INDIRECT("J"&ROW()&":J"&(ROW()+2))),"") -> 3123.9153 | O74: 1260.403 | Q74: =IF(MOD(ROW()-14,3)=0,AVERAGE(INDIRECT("O"&ROW()&":O"&(ROW()+2))),"") -> 1257.207 | R74: 1185.6873
J75: 3123.595 | K75: =IF(MOD(ROW()-14,3)=0,AVERAGE(INDIRECT("J"&ROW()&":J"&(ROW()+2))),"") | O75: 1258.014 | Q75: =IF(MOD(ROW()-14,3)=0,AVERAGE(INDIRECT("O"&ROW()&":O"&(ROW()+2))),"") | R75: 1172.1103
J76: 3125.084 | K76: =IF(MOD(ROW()-14,3)=0,AVERAGE(INDIRECT("J"&ROW()&":J"&(ROW()+2))),"") | O76: 1253.204 | Q76: =IF(MOD(ROW()-14,3)=0,AVERAGE(INDIRECT("O"&ROW()&":O"&(ROW()+2))),"") | R76: 1166.1633
J77: 3129.769 | K77: =IF(MOD(ROW()-14,3)=0,AVERAGE(INDIRECT("J"&ROW()&":J"&(ROW()+2))),"") -> 3137.4753 | O77: 1252.291 | Q77: =IF(MOD(ROW()-14,3)=0,AVERAGE(INDIRECT("O"&ROW()&":O"&(ROW()+2))),"") -> 1250.819 | R77: 1168.5713
J78: 3139.955 | K78: =IF(MOD(ROW()-14,3)=0,AVERAGE(INDIRECT("J"&ROW()&":J"&(ROW()+2))),"") | O78: 1250.512 | Q78: =IF(MOD(ROW()-14,3)=0,AVERAGE(INDIRECT("O"&ROW()&":O"&(ROW()+2))),"") | R78: 1166.2773
J79: 3142.702 | K79: =IF(MOD(ROW()-14,3)=0,AVERAGE(INDIRECT("J"&ROW()&":J"&(ROW()+2))),"") | O79: 1249.654 | Q79: =IF(MOD(ROW()-14,3)=0,AVERAGE(INDIRECT("O"&ROW()&":O"&(ROW()+2))),"") | R79: 1160.009
J80: 3148.552 | K80: =IF(MOD(ROW()-14,3)=0,AVERAGE(INDIRECT("J"&ROW()&":J"&(ROW()+2))),"") -> 3152.2323 | O80: 1247.387 | Q80: =IF(MOD(ROW()-14,3)=0,AVERAGE(INDIRECT("O"&ROW()&":O"&(ROW()+2))),"") -> 1245.9867 | R80: 1149.4453
J81: 3149.526 | K81: =IF(MOD(ROW()-14,3)=0,AVERAGE(INDIRECT("J"&ROW()&":J"&(ROW()+2))),"") | O81: 1245.719 | Q81: =IF(MOD(ROW()-14,3)=0,AVERAGE(INDIRECT("O"&ROW()&":O"&(ROW()+2))),"") | R81: 1133.5283
...

Sheet IPC_trim
B1: IPC empalmado | C1: IPC trim
A2: 38626 | B2: 8.6013862 | G2: 2012 | H2: Primer Trimestre | I2: 26.480708 | J2: =+(I2/$I$2)*100 -> 100
A3: 38657 | B3: 8.6969078 | H3: Segundo Trimestre | I3: 28.225273 | J3: =+(I3/$I$2)*100 -> 106.58806
A4: 38687 | B4: 8.7317102 | H4: Tercer Trimestre | I4: 29.720544 | J4: =+(I4/$I$2)*100 -> 112.2347
A5: 38718 | B5: 8.8353771 | H5: Cuarto Trimestre | I5: 31.091414 | J5: =+(I5/$I$2)*100 -> 117.41157
A6: 38749 | B6: 8.852408 | G6: 2013 | H6: Primer Trimestre | I6: 32.862883 | J6: =+(I6/$I$2)*100 -> 124.10123
A7: 38777 | B7: 8.9249748 | H7: Segundo Trimestre | I7: 34.932024 | J7: =+(I7/$I$2)*100 -> 131.91499
A8: 38808 | B8: 8.9753273 | H8: Tercer Trimestre | I8: 37.201094 | J8: =+(I8/$I$2)*100 -> 140.48376
A9: 38838 | B9: 9.0056869 | H9: Cuarto Trimestre | I9: 40.355034 | J9: =+(I9/$I$2)*100 -> 152.39409
A10: 38869 | B10: 9.0523369 | G10: 2014 | H10: Primer Trimestre | I10: 46.03425 | J10: =+(I10/$I$2)*100 -> 173.8407
A11: 38899 | B11: 9.0797346 | H11: Segundo Trimestre | I11: 50.446755 | J11: =+(I11/$I$2)*100 -> 190.5038
A12: 38930 | B12: 9.0975061 | H12: Tercer Trimestre | I12: 53.920334 | J12: =+(I12/$I$2)*100 -> 203.6212
A13: 38961 | B13: 9.1360109 | H13: Cuarto Trimestre | I13: 56.995537 | J13: =+(I13/$I$2)*100 -> 215.23419
A14: 38991 | B14: 9.18118 | G14: 2015 | H14: Primer Trimestre | I14: 59.894507 | J14: =+(I14/$I$2)*100 -> 226.18167
A15: 39022 | B15: 9.2767016 | H15: Segundo Trimestre | I15: 63.268369 | J15: =+(I15/$I$2)*100 -> 238.9225
A16: 39052 | B16: 9.427759 | H16: Tercer Trimestre | I16: 67.003831 | J16: =+(I16/$I$2)*100 -> 253.02885
A17: 39083 | B17: 9.5329068 | H17: Cuarto Trimestre | I17: 72.333047 | J17: =+(I17/$I$2)*100 -> 273.15375
A18: 39114 | B18: 9.5958474 | G18: 2016 | H18: Primer Trimestre | I18: 81.518423 | J18: =+(I18/$I$2)*100 -> 307.8408
A19: 39142 | B19: 9.6958119 | H19: Segundo Trimestre | I19: 89.559021 | J19: =+(I19/$I$2)*100 -> 338.20478
A20: 39173 | B20: 9.9157337 | H20: Tercer Trimestre | I20: 94.653506 | J20: =+(I20/$I$2)*100 -> 357.44326
A21: 39203 | B21: 10.122327 | H21: Cuarto Trimestre | I21: 99.004305 | J21: =+(I21/$I$2)*100 -> 373.87333
A22: 39234 | B22: 10.39112 | G22: 2017 | H22: Primer Trimestre | I22: 103.8 | J22: =+(I22/$I$2)*100 -> 391.98348
A23: 39264 | B23: 10.656211 | H23: Segundo Trimestre | I23: 110.43333 | J23: =+(I23/$I$2)*100 -> 417.03316
A24: 39295 | B24: 11.010159 | H24: Tercer Trimestre | I24: 115.6 | J24: =+(I24/$I$2)*100 -> 436.54422
A25: 39326 | B25: 11.230822 | H25: Cuarto Trimestre | I25: 121.73333 | J25: =+(I25/$I$2)*100 -> 459.70573
A26: 39356 | B26: 11.391505 | G26: 2018 | H26: Primer Trimestre | I26: 130.06667 | J26: =+(I26/$I$2)*100 -> 491.17518
A27: 39387 | B27: 11.345596 | H27: Segundo Trimestre | I27: 140.4 | J27: =+(I27/$I$2)*100 -> 530.1973
A28: 39417 | B28: 11.456667 | H28: Tercer Trimestre | I28: 156.53333 | J28: =+(I28/$I$2)*100 -> 591.12216
A29: 39448 | B29: 11.688437 | H29: Cuarto Trimestre | I29: 179.33333 | J29: =+(I29/$I$2)*100 -> 677.22258
A30: 39479 | B30: 11.949825 | G30: 2019 | H30: Primer Trimestre | I30: 197.46667 | J30: =+(I30/$I$2)*100 -> 745.7001
A31: 39508 | B31: 12.435578 | H31: Segundo Trimestre | I31: 219.4 | J31: =+(I31/$I$2)*100 -> 828.52769
A32: 39539 | B32: 12.807298 | H32: Tercer Trimestre | I32: 241.26667 | J32: =+(I32/$I$2)*100 -> 911.10353
A33: 39569 | B33: 12.839139 | H33: Cuarto Trimestre | I33: 272.9 | J33: =+(I33/$I$2)*100 -> 1030.5616
A34: 39600 | B34: 13.150139 | G34: 2020 | H34: Primer Trimestre | I34: 297.03333 | J34: =+(I34/$I$2)*100 -> 1121.6971
A35: 39630 | B35: 13.334518 | H35: Segundo Trimestre | I35: 315.66667 | J35: =+(I35/$I$2)*100 -> 1192.0628
A36: 39661 | B36: 13.443368 | H36: Tercer Trimestre | I36: 337.3 | J36: =+(I36/$I$2)*100 -> 1273.7575
A37: 39692 | B37: 13.588502 | H37: Cuarto Trimestre | I37: 372.2 | J37: =+(I37/$I$2)*100 -> 1405.5515
A38: 39722 | B38: 13.667733 | G38: 2021 | H38: Primer Trimestre | I38: 417.76667 | J38: =+(I38/$I$2)*100 -> 1577.6265
A39: 39753 | B39: 13.755109 | H39: Segundo Trimestre | I39: 468.66667 | J39: =+(I39/$I$2)*100 -> 1769.8419
A40: 39783 | B40: 13.816569 | H40: Tercer Trimestre | I40: 512.33333 | J40: =+(I40/$I$2)*100 -> 1934.7418
...

Sheet borador
A1: Fecha | B1: Salarios_Totales_Trim | D1: IPC base 100 2012Q1 | E1: Salarios_Reales_Totales_Trim
A2: 40999 | B2: =+(C2/$C$2)*100 -> 100 | C2: 28.864731 | D2: =+IPC_trim!J2 -> 100 | E2: =+(B2/D2)*100 -> 100
A3: 41090 | B3: =+(C3/$C$2)*100 -> 106.67014 | C3: 30.79005 | D3: =+IPC_trim!J3 -> 106.58806 | E3: =+(B3/D3)*100 -> 100.07701
A4: 41182 | B4: =+(C4/$C$2)*100 -> 113.77673 | C4: 32.841349 | D4: =+IPC_trim!J4 -> 112.2347 | E4: =+(B4/D4)*100 -> 101.37393
A5: 41274 | B5: =+(C5/$C$2)*100 -> 119.52601 | C5: 34.500862 | D5: =+IPC_trim!J5 -> 117.41157 | E5: =+(B5/D5)*100 -> 101.80088
A6: 41364 | B6: =+(C6/$C$2)*100 -> 123.92356 | C6: 35.770203 | D6: =+IPC_trim!J6 -> 124.10123 | E6: =+(B6/D6)*100 -> 99.856839
A7: 41455 | B7: =+(C7/$C$2)*100 -> 133.14459 | C7: 38.43183 | D7: =+IPC_trim!J7 -> 131.91499 | E7: =+(B7/D7)*100 -> 100.93212
A8: 41547 | B8: =+(C8/$C$2)*100 -> 142.62459 | C8: 41.168206 | D8: =+IPC_trim!J8 -> 140.48376 | E8: =+(B8/D8)*100 -> 101.5239
A9: 41639 | B9: =+(C9/$C$2)*100 -> 150.61693 | C9: 43.475174 | D9: =+IPC_trim!J9 -> 152.39409 | E9: =+(B9/D9)*100 -> 98.833841
A10: 41729 | B10: =+(C10/$C$2)*100 -> 159.38502 | C10: 46.006057 | D10: =+IPC_trim!J10 -> 173.8407 | E10: =+(B10/D10)*100 -> 91.684521
A11: 41820 | B11: =+(C11/$C$2)*100 -> 177.01982 | C11: 51.096297 | D11: =+IPC_trim!J11 -> 190.5038 | E11: =+(B11/D11)*100 -> 92.921939
A12: 41912 | B12: =+(C12/$C$2)*100 -> 192.55211 | C12: 55.57965 | D12: =+IPC_trim!J12 -> 203.6212 | E12: =+(B12/D12)*100 -> 94.563884
A13: 42004 | B13: =+(C13/$C$2)*100 -> 202.05087 | C13: 58.321442 | D13: =+IPC_trim!J13 -> 215.23419 | E13: =+(B13/D13)*100 -> 93.874896
... A55: 45838 | B55: =+(C55/$C$2)*100 -> 23409.179 | C55: 6756.9967 | D55: =+IPC_trim!J55 -> 32924.22 | E55: =+(B55/D55)*100 -> 71.100177

Sheet borador_2
D2: Meses | E2: Base abr2012 =100 | F2: Base oct2016 =100 | L2: Jota de Joaco
D3: 40909 | E3: 94.532015 | F3: =+E3/$E$48*$F$48 -> 28.470289 | H3: Años (Meses) | I3: Trimestres (Meses) | J3: Promedio de Base oct2016 =100
D4: 40940 | E4: 95.727536 | F4: =+E4/$E$48*$F$48 -> 28.830345 | H4: 2012 | I4: Trim.1 | J4: 28.864731
D5: 40969 | E5: 97.26558 | F5: =+E5/$E$48*$F$48 -> 29.29356 | I5: Trim.2 | J5: 30.79005
D6: 41000 | E6: 99.999515 | F6: =+E6/$E$48*$F$48 -> 30.116941 | I6: Trim.3 | J6: 32.841349
D7: 41030 | E7: 102.34511 | F7: =+E7/$E$48*$F$48 -> 30.823365 | I7: Trim.4 | J7: 34.500862
D8: 41061 | E8: 104.35884 | F8: =+E8/$E$48*$F$48 -> 31.429844 | H8: 2013 | I8: Trim.1 | J8: 35.770203
D9: 41091 | E9: 107.02365 | F9: =+E9/$E$48*$F$48 -> 32.232405 | I9: Trim.2 | J9: 38.43183
D10: 41122 | E10: 109.31867 | F10: =+E10/$E$48*$F$48 -> 32.923599 | I10: Trim.3 | J10: 41.168206
D11: 41153 | E11: 110.79439 | F11: =+E11/$E$48*$F$48 -> 33.368042 | I11: Trim.4 | J11: 43.475174
D12: 41183 | E12: 112.29014 | F12: =+E12/$E$48*$F$48 -> 33.818519 | H12: 2014 | I12: Trim.1 | J12: 46.006057
D13: 41214 | E13: 114.89276 | F13: =+E13/$E$48*$F$48 -> 34.602353 | I13: Trim.2 | J13: 51.096297
D14: 41244 | E14: 116.48441 | F14: =+E14/$E$48*$F$48 -> 35.081712 | I14: Trim.3 | J14: 55.57965
D15: 41275 | E15: 117.20753 | F15: =+E15/$E$48*$F$48 -> 35.299494 | I15: Trim.4 | J15: 58.321442
D16: 41306 | E16: 118.02953 | F16: =+E16/$E$48*$F$48 -> 35.547056 | H16: 2015 | I16: Trim.1 | J16: 61.191062
D17: 41334 | E17: 121.07432 | F17: =+E17/$E$48*$F$48 -> 36.464059 | I17: Trim.2 | J17: 65.607603
D18: 41365 | E18: 123.67204 | F18: =+E18/$E$48*$F$48 -> 37.246417 | I18: Trim.3 | J18: 71.996095
D19: 41395 | E19: 128.24043 | F19: =+E19/$E$48*$F$48 -> 38.622282 | I19: Trim.4 | J19: 75.916155
D20: 41426 | E20: 130.9117 | F20: =+E20/$E$48*$F$48 -> 39.42679 | H20: 2016 | I20: Trim.1 | J20: 79.908142
D21: 41456 | E21: 133.92979 | F21: =+E21/$E$48*$F$48 -> 40.335751 | I21: Trim.2 | J21: 87.806488
D22: 41487 | E22: 136.47143 | F22: =+E22/$E$48*$F$48 -> 41.10122 | I22: Trim.3 | J22: 95.884442
D23: 41518 | E23: 139.68033 | F23: =+E23/$E$48*$F$48 -> 42.067648 | I23: Trim.4 | J23: 101.4
D24: 41548 | E24: 141.5218 | F24: =+E24/$E$48*$F$48 -> 42.622245 | H24: 2017 | I24: Trim.1 | J24: 106.32
D25: 41579 | E25: 144.91122 | F25: =+E25/$E$48*$F$48 -> 43.643039 | I25: Trim.2 | J25: 114.50333
D26: 41609 | E26: 146.62851 | F26: =+E26/$E$48*$F$48 -> 44.160236 | I26: Trim.3 | J26: 123.58667
D27: 41640 | E27: 149.17216 | F27: =+E27/$E$48*$F$48 -> 44.926308 | I27: Trim.4 | J27: 129.42
D28: 41671 | E28: 152.33684 | F28: =+E28/$E$48*$F$48 -> 45.87942 | H28: 2018 | I28: Trim.1 | J28: 134.07
D29: 41699 | E29: 156.76298 | F29: =+E29/$E$48*$F$48 -> 47.212443 | I29: Trim.2 | J29: 141.62667
D30: 41730 | E30: 164.52122 | F30: =+E30/$E$48*$F$48 -> 49.548999 | I30: Trim.3 | J30: 151.13
D31: 41760 | E31: 169.6818 | F31: =+E31/$E$48*$F$48 -> 51.103217 | I31: Trim.4 | J31: 165.63
D32: 41791 | E32: 174.77346 | F32: =+E32/$E$48*$F$48 -> 52.636674 | H32: 2019 | I32: Trim.1 | J32: 180.65667
D33: 41821 | E33: 180.76322 | F33: =+E33/$E$48*$F$48 -> 54.440617 | I33: Trim.2 | J33: 196.02
D34: 41852 | E34: 184.88789 | F34: =+E34/$E$48*$F$48 -> 55.682848 | I34: Trim.3 | J34: 215.23
D35: 41883 | E35: 187.9846 | F35: =+E35/$E$48*$F$48 -> 56.615485 | I35: Trim.4 | J35: 233.56
D36: 41913 | E36: 190.91576 | F36: =+E36/$E$48*$F$48 -> 57.498266 | H36: 2020 | I36: Trim.1 | J36: 262.97
D37: 41944 | E37: 194.03767 | F37: =+E37/$E$48*$F$48 -> 58.438494 | I37: Trim.2 | J37: 272.44667
D38: 41974 | E38: 195.99361 | F38: =+E38/$E$48*$F$48 -> 59.027565 | I38: Trim.3 | J38: 284.43667
D39: 42005 | E39: 199.8258 | F39: =+E39/$E$48*$F$48 -> 60.18171 | I39: Trim.4 | J39: 311.42667
D40: 42036 | E40: 201.66569 | F40: =+E40/$E$48*$F$48 -> 60.735832 | H40: 2021 | I40: Trim.1 | J40: 344.06
D41: 42064 | E41: 208.04018 | F41: =+E41/$E$48*$F$48 -> 62.655643 | I41: Trim.2 | J41: 381.80667
...
